<?xml version="1.0" encoding="utf-8"?>
<!-- =================================================================================== -->
<!--   Copyright 2019 ANYbotics, https://www.anybotics.com                               -->
<!-- =================================================================================== -->
<!-- This file contains the description of the ANYmal B robot. -->
<?xml version="1.0" ?>
<robot name="anymal">

    <!--
      Material colors
    -->

    <!-- Basic colors -->
    <material name="black">
        <color rgba="0.0 0.0 0.0 1.0"/>
    </material>
    <material name="blue">
        <color rgba="0.0 0.0 0.8 1.0"/>
    </material>
    <material name="green">
        <color rgba="0.0 0.8 0.0 1.0"/>
    </material>
    <material name="grey">
        <color rgba="0.2 0.2 0.2 1.0"/>
    </material>
    <material name="light_grey">
        <color rgba="0.4 0.4 0.4 1.0"/>
    </material>
    <material name="red">
        <color rgba="0.8 0.0 0.0 1.0"/>
    </material>
    <material name="white">
        <color rgba="1.0 1.0 1.0 1.0"/>
    </material>

    <!-- Material for the visual primitives -->
    <material name="anymal_material">
        <color rgba="0.7 0.7 0.7 1.0"/>
    </material>

    <!--
      Base
    -->

    <link name="base">
        <visual>
            <origin rpy="0 0 0" xyz="0 0 0"/>
            <geometry>
                 <sphere radius="0.075"/>
            </geometry>
        </visual>
        <!-- Main Body -->
        <collision>
            <origin rpy="0 0 0" xyz="0 0 0"/>
            <geometry>
                <sphere radius="0.075"/>
            </geometry>
        </collision>
    </link>
    <!-- Fixed joint to add dummy inertia link -->
    <joint name="base_to_base_inertia" type="fixed">
        <parent link="base"/>
        <child link="base_inertia"/>
        <origin rpy="0 0 0" xyz="0 0 0"/>
    </joint>
    <!-- Dummy inertia link, because KDL cannot have inertia on the base link -->
    <link name="base_inertia">
        <visual>
            <origin rpy="0 0 0" xyz="0 0 0"/>
            <geometry>
                 <sphere radius="0.075"/>
            </geometry>
        </visual>
        <inertial>
            <origin rpy="0 0 0" xyz="0.07 0 0"/>
            <mass value="3"/>
            <inertia ixx="0.00005" ixy="0" ixz="0" iyy="0.00005" iyz="0" izz="0.00005"/>
        </inertial>
    </link>


    <!--
      Left-Fore leg
    -->
    
    <!-- Hip joint -->
    <joint name="LF_HAA" type="revolute">
        <parent link="base"/>
        <child link="LF_HIP"/>
        <origin xyz="0 0 0"/>
        <axis xyz="1 0 0"/>
        <limit effort="320" lower="-6.28" upper="6.28" velocity="20"/>
        <dynamics damping="0.0" friction="0.0"/>
    </joint>
    
    <!-- high link -->
    <link name="LF_HIP">
    </link>
    
    <joint name="LF_HFE" type="revolute">
        <parent link="LF_HIP"/>
        <child link="LF_THIGH"/>
        <origin xyz="0 0 0"/>
        <axis xyz="0 1 0"/>
        <limit effort="320" lower="-6.28" upper="6.28" velocity="20"/>
        <dynamics damping="0.0" friction="0.0"/>
    </joint>

    <!-- Thigh link -->
    <link name="LF_THIGH">
        <visual>
            <origin rpy="0 0.7853981634 0.0" xyz="-0.154 0 -0.154"/>
            <geometry>
                <cylinder length="0.27" radius="0.025"/>
            </geometry>
        </visual>
        <collision>
            <!-- KFE actuator -->
            <origin rpy="0 0.7853981634 0.0" xyz="-0.154 0 -0.154"/>
            <geometry>
                <cylinder length="0.27" radius="0.025"/>
            </geometry>
        </collision>
        <inertial>
            <origin rpy="0 0.7853981634 0" xyz="-0.154 0 -0.154"/>
            <mass value="0.5"/>
            <inertia ixx="0.001744791667" ixy="0" ixz="0" iyy="0.001744791667" iyz="0" izz="0.00015625"/>
        </inertial>
    </link>

    <!-- guard joint -->
    <joint name="guard" type="fixed">
        <parent link="LF_THIGH"/>
        <child link="guardlink"/>
        <origin xyz="-0.28 0 -0.28"/>
    </joint>
    <link name="guardlink">
        <visual>
            <origin rpy="0 -0.7853981634 0" xyz="0 0 0"/>
            <geometry>
                <sphere radius="0.04"/>
            </geometry>
        </visual>
        <collision>
            <origin rpy="0 -0.7853981634 0" xyz="0 0 0"/>
            <geometry>
                <sphere radius="0.04"/>
            </geometry>
        </collision>
    </link>    
    <!-- Adapter to Foot joint -->    

    <!-- LF_KFE joint -->
    <joint name="LF_KFE" type="revolute">
        <parent link="LF_THIGH"/>
        <child link="LF_SHANK"/>
        <origin xyz="-0.28 0 -0.28"/>
        <axis xyz="0 1 0"/>
        <limit effort="320" lower="-6.28" upper="6.28" velocity="20"/>
        <dynamics damping="0.0" friction="0.0"/>
    </joint>
    <link name="LF_SHANK">
        <visual>
            <origin rpy="0 -0.7853981634 0" xyz="0.13 0 -0.13"/>
            <geometry>
                <cylinder length="0.35" radius="0.025"/>
            </geometry>
        </visual>
        <collision>
            <!-- KFE actuator -->
            <origin rpy="0 -0.7853981634 0.0" xyz="0.13 0 -0.13"/>
            <geometry>
                <cylinder length="0.35" radius="0.025"/>
            </geometry>
        </collision>
        <inertial>
            <origin rpy="0 -0.7853981634 0.0" xyz="0.135 0 -0.135"/>
            <mass value="0.5"/>
            <inertia ixx="0.001744791667" ixy="0" ixz="0" iyy="0.001744791667" iyz="0" izz="0.00015625"/>
        </inertial>
    </link>

    <joint name="FOOT" type="fixed">
        <parent link="LF_SHANK"/>
        <child link="LF_FOOT"/>
        <origin rpy="0.0 0.0 0.0" xyz="0.24 0.0 -0.24"/>
    </joint>

    <!-- Foot link -->
    <link name="LF_FOOT">
        <visual>
            <origin rpy="0 0 0" xyz="0 0 0"/>
            <geometry>
                <sphere radius="0.055"/>
            </geometry>
        </visual>
        <collision>
            <origin xyz="0 0 0"/>
            <geometry>
                <sphere radius="0.055"/>
            </geometry>
        </collision>
    </link>

</robot>
