<?xml version="1.0" encoding="utf-8"?>
<!-- =================================================================================== -->
<!--   Copyright 2019 ANYbotics, https://www.anybotics.com                               -->
<!-- =================================================================================== -->
<!-- This file contains the description of the ANYmal B robot. -->
<?xml version="1.0" ?>
<robot name="jumpingrobot">

    <!--
      Material colors
    -->

    <!-- Basic colors -->
    <material name="black">
        <color rgba="0.0 0.0 0.0 1.0"/>
    </material>
    <material name="blue">
        <color rgba="0.0 0.0 0.8 1.0"/>
    </material>
    <material name="green">
        <color rgba="0.0 0.8 0.0 1.0"/>
    </material>
    <material name="grey">
        <color rgba="0.2 0.2 0.2 1.0"/>
    </material>
    <material name="light_grey">
        <color rgba="0.4 0.4 0.4 1.0"/>
    </material>
    <material name="red">
        <color rgba="0.8 0.0 0.0 1.0"/>
    </material>
    <material name="white">
        <color rgba="1.0 1.0 1.0 1.0"/>
    </material>

    <!-- Material for the visual primitives -->
    <material name="anymal_material">
        <color rgba="0.7 0.7 0.7 1.0"/>
    </material>

    <!--
      Base
    -->

    <!-- Base link -->
    <link name="base">
        <visual>
            <origin rpy="0 0 0" xyz="0.0635 0.15 0.7"/>
            <geometry>
                 <sphere radius="0.075"/>
            </geometry>
        </visual>
        <!-- Main Body -->
        <collision>
            <origin rpy="0 0 0" xyz="0.0635 0.15 0.7"/>
            <geometry>
                <sphere radius="0.075"/>
            </geometry>
        </collision>
    </link>
    <!-- Fixed joint to add dummy inertia link -->
    <joint name="base_to_base_inertia" type="fixed">
        <parent link="base"/>
        <child link="base_inertia"/>
        <origin rpy="0 0 0" xyz="0.0635 0.15 0.7"/>
    </joint>
    <!-- Dummy inertia link, because KDL cannot have inertia on the base link -->
    <link name="base_inertia">
        <visual>
            <origin rpy="0 0 0" xyz="0 0 0"/>
            <geometry>
                 <sphere radius="0.075"/>
            </geometry>
        </visual>
        <inertial>
            <origin rpy="0 0 0" xyz="0 0 0"/>
            <mass value="1"/>
            <inertia ixx="0.0025" ixy="0" ixz="0" iyy="0.0025" iyz="0" izz="0.0025"/>
        </inertial>
    </link>

    <!--
      Left-Fore leg
    -->
    <!-- high link -->
    <!-- Hip joint -->

    <!-- high link -->
    <link name="LF_HIP">
        <visual>
            <origin rpy="0 0 0.0" xyz="0 0 0"/>
            <geometry>
                <mesh filename="../meshes/anymal_hip_l.dae" scale="0.001 0.001 0.001"/>
            </geometry>
        </visual>
        <inertial>
            <origin rpy="0 0 0" xyz="0.064516258147 -0.003787101702 -0.000152184388"/>
            <mass value="0.4748735467"/>
            <inertia ixx="8.10077832e-04" ixy="−5.100799033e-06" ixz="−7.273031785e-06" iyy="7.6752413e-04" iyz="8.824340424e-06" izz="6.60225308e-04"/>
        </inertial>
    </link>
    <!-- Hip joint -->
    <joint name="LF_HAA" type="revolute">
        <parent link="base"/>
        <child link="LF_HIP"/>
        <origin xyz="0 0 0.58"/>
        <axis xyz="1 0 0"/>
        <limit effort="1000" lower="-1.5" upper="1.5" velocity="15"/>
        <dynamics damping="0.0" friction="0.0"/>
    </joint>

    <!-- Thigh link -->
    <link name="LF_THIGH">
        <visual>
            <origin rpy="0 0 0.0" xyz="0 0 0"/>
            <geometry>
                <mesh filename="../meshes/anymal_thigh_l.dae" scale="0.001 0.001 0.001"/>
            </geometry>
        </visual>
        <collision>
            <!-- KFE actuator -->
            <origin rpy="1.57079632679 0 0" xyz="0.0 0.07205 -0.25"/>
            <geometry>
                <cylinder length="0.11" radius="0.06"/>
            </geometry>
        </collision>
        <inertial>
            <origin rpy="0 0 0" xyz="-0.003897968082 0.054226618537 -0.214583373795"/>
            <mass value="0.5449921557"/>
            <inertia ixx="0.004012264812" ixy="2.254021735e-05" ixz="9.59354468e-05" iyy="0.004021454598" iyz="-4.68700437e-04" izz="8.31408583e-04"/>
        </inertial>
    </link>
    <!-- Thigh joint -->
    <joint name="LF_HFE" type="revolute">
        <parent link="LF_HIP"/>
        <child link="LF_THIGH"/>
        <origin xyz="0.0635                    0.041                    0.0"/>
        <axis xyz="0 1 0"/>
        <limit effort="1000" lower="-6.28" upper="6.28" velocity="15"/>
        <dynamics damping="0.0" friction="0.0"/>
    </joint>

    <!-- Shank link -->
    <link name="LF_SHANK">
        <visual>
            <origin rpy="0 0 0.0" xyz="0 0 0"/>
            <geometry>
                <mesh filename="../meshes/anymal_shank_l.dae" scale="0.001 0.001 0.001"/>
            </geometry>
        </visual>
        <inertial>
            <origin rpy="0 0 0" xyz="0.030816858139 -0.004617229294 0.000893125713"/>
            <mass value="0.06906810067"/>
            <inertia ixx="7.01626749e-05" ixy="-1.891699345e-05" ixz="3.375899797e-06" iyy="2.25423403e-04" iyz="-2.742896747e-07" izz="1.81677558e-04"/>
        </inertial>
    </link>
    <!-- Shank joint -->
    <joint name="LF_KFE" type="revolute">
        <parent link="LF_THIGH"/>
        <child link="LF_SHANK"/>
        <origin xyz="0.0 0.109 -0.25"/>
        <axis xyz="0 1 0"/>
        <limit effort="1000" lower="-6.28" upper="6.28" velocity="15"/>
        <dynamics damping="0.0" friction="0.0"/>
    </joint>
    <!-- Shank to Adapter joint -->
    <joint name="LF_SHANK_TO_ADAPTER" type="fixed">
        <parent link="LF_SHANK"/>
        <child link="LF_ADAPTER"/>
        <origin rpy="0.0 0.0 0.0" xyz="0.1 -0.02 0.0"/>
    </joint>

    <!-- Adapter link -->
    <link name="LF_ADAPTER">
        <visual>
            <origin rpy="0 0 0.0" xyz="0 0 0.032"/>
            <geometry>
                <mesh filename="../meshes/anymal_foot.dae" scale="0.001 0.001 0.001"/>
            </geometry>
        </visual>
        <collision>
            <origin rpy="0 0 0" xyz="0 0 -0.160625"/>
            <geometry>
                <cylinder length="0.22125" radius="0.015"/>
            </geometry>
        </collision>
        <inertial>
            <origin rpy="0 0 0" xyz="-8.66e-10 -1.472e-09 -0.244345749188"/>
            <mass value="0.046723589"/>
            <inertia ixx="5.3312914e-04" ixy="-3.106666667e-13" ixz="3.463333333e-12" iyy="5.3312914e-04" iyz="5.854333333e-12" izz="1.814105911e-05"/>
        </inertial>
    </link>
    <!-- Adapter to Foot joint -->
    <joint name="LF_ADAPTER_TO_FOOT" type="fixed">
        <parent link="LF_ADAPTER"/>
        <child link="LF_FOOT"/>
        <origin rpy="0.0 0.0 0.0" xyz="0.0 0.0 -0.32125"/>
    </joint>

    <!-- Foot link -->
    <link name="LF_FOOT">
        <collision>
            <origin xyz="0 0 0.02325"/>
            <geometry>
                <sphere radius="0.035"/>
            </geometry>
        </collision>
    </link>

</robot>
